Watching for file changes with StatReloader
/home/loupix/Documents/youtubeDownloader/app/urls.py changed, reloading.
Watching for file changes with StatReloader
HTTP GET / 200 [0.24, 192.168.1.189:44922]
HTTP GET /static/build/app.css 200 [0.87, 192.168.1.189:44926]
HTTP GET /static/build/app.js 200 [0.73, 192.168.1.189:44940]
HTTP GET /static/favicon/favicon-32x32.png 200 [0.30, 192.168.1.189:45126]
HTTP GET /static/favicon/manifest.json 200 [0.28, 192.168.1.189:45134]
HTTP GET /static/favicon/android-icon-192x192.png 200 [0.02, 192.168.1.189:45138]
HTTP GET /test 301 [0.01, 192.168.1.189:33102]
HTTP GET /test/ 200 [0.04, 192.168.1.189:33108]
/home/loupix/Documents/youtubeDownloader/app/urls.py changed, reloading.
Watching for file changes with StatReloader
HTTP GET /favicon.ico 404 [0.08, 192.168.1.189:60310]
/home/loupix/Documents/youtubeDownloader/app/urls.py changed, reloading.
Watching for file changes with StatReloader
/home/loupix/Documents/youtubeDownloader/app/urls.py changed, reloading.
Watching for file changes with StatReloader
HTTP GET /test/ 200 [0.03, 192.168.1.189:52314]
/home/loupix/Documents/youtubeDownloader/app/urls.py changed, reloading.
Watching for file changes with StatReloader
HTTP GET /test/ 200 [0.02, 192.168.1.189:49606]
HTTP GET /test/ 200 [0.03, 192.168.1.189:39412]
/home/loupix/Documents/youtubeDownloader/app/urls.py changed, reloading.
Watching for file changes with StatReloader
Exception in thread django-main-thread:
Traceback (most recent call last):
  File "/usr/lib/python3.10/threading.py", line 1009, in _bootstrap_inner
    self.run()
  File "/usr/lib/python3.10/threading.py", line 946, in run
    self._target(*self._args, **self._kwargs)
  File "/home/loupix/Documents/youtubeDownloader/env/lib/python3.10/site-packages/django/utils/autoreload.py", line 64, in wrapper
    fn(*args, **kwargs)
  File "/home/loupix/Documents/youtubeDownloader/env/lib/python3.10/site-packages/channels/management/commands/runserver.py", line 75, in inner_run
    self.check(display_num_errors=True)
  File "/home/loupix/Documents/youtubeDownloader/env/lib/python3.10/site-packages/django/core/management/base.py", line 475, in check
    all_issues = checks.run_checks(
  File "/home/loupix/Documents/youtubeDownloader/env/lib/python3.10/site-packages/django/core/checks/registry.py", line 88, in run_checks
    new_errors = check(app_configs=app_configs, databases=databases)
  File "/home/loupix/Documents/youtubeDownloader/env/lib/python3.10/site-packages/django/core/checks/urls.py", line 14, in check_url_config
    return check_resolver(resolver)
  File "/home/loupix/Documents/youtubeDownloader/env/lib/python3.10/site-packages/django/core/checks/urls.py", line 24, in check_resolver
    return check_method()
  File "/home/loupix/Documents/youtubeDownloader/env/lib/python3.10/site-packages/django/urls/resolvers.py", line 476, in check
    for pattern in self.url_patterns:
  File "/home/loupix/Documents/youtubeDownloader/env/lib/python3.10/site-packages/django/utils/functional.py", line 57, in __get__
    res = instance.__dict__[self.name] = self.func(instance)
  File "/home/loupix/Documents/youtubeDownloader/env/lib/python3.10/site-packages/django/urls/resolvers.py", line 690, in url_patterns
    patterns = getattr(self.urlconf_module, "urlpatterns", self.urlconf_module)
  File "/home/loupix/Documents/youtubeDownloader/env/lib/python3.10/site-packages/django/utils/functional.py", line 57, in __get__
    res = instance.__dict__[self.name] = self.func(instance)
  File "/home/loupix/Documents/youtubeDownloader/env/lib/python3.10/site-packages/django/urls/resolvers.py", line 683, in urlconf_module
    return import_module(self.urlconf_name)
  File "/usr/lib/python3.10/importlib/__init__.py", line 126, in import_module
    return _bootstrap._gcd_import(name[level:], package, level)
  File "<frozen importlib._bootstrap>", line 1050, in _gcd_import
  File "<frozen importlib._bootstrap>", line 1027, in _find_and_load
  File "<frozen importlib._bootstrap>", line 1006, in _find_and_load_unlocked
  File "<frozen importlib._bootstrap>", line 688, in _load_unlocked
  File "<frozen importlib._bootstrap_external>", line 883, in exec_module
  File "<frozen importlib._bootstrap>", line 241, in _call_with_frames_removed
  File "/home/loupix/Documents/youtubeDownloader/youtubeDownload/urls.py", line 24, in <module>
    path('', include('app.urls')),
  File "/home/loupix/Documents/youtubeDownloader/env/lib/python3.10/site-packages/django/urls/conf.py", line 38, in include
    urlconf_module = import_module(urlconf_module)
  File "/usr/lib/python3.10/importlib/__init__.py", line 126, in import_module
    return _bootstrap._gcd_import(name[level:], package, level)
  File "<frozen importlib._bootstrap>", line 1050, in _gcd_import
  File "<frozen importlib._bootstrap>", line 1027, in _find_and_load
  File "<frozen importlib._bootstrap>", line 1006, in _find_and_load_unlocked
  File "<frozen importlib._bootstrap>", line 688, in _load_unlocked
  File "<frozen importlib._bootstrap_external>", line 883, in exec_module
  File "<frozen importlib._bootstrap>", line 241, in _call_with_frames_removed
  File "/home/loupix/Documents/youtubeDownloader/app/urls.py", line 14, in <module>
    path(r'^ws/test/$', TestChannels.as_asgi()),
NameError: name 'TestChannels' is not defined. Did you mean: 'AppChannels'?
/home/loupix/Documents/youtubeDownloader/app/channels.py changed, reloading.
Watching for file changes with StatReloader
Exception in thread django-main-thread:
Traceback (most recent call last):
  File "/usr/lib/python3.10/threading.py", line 1009, in _bootstrap_inner
    self.run()
  File "/usr/lib/python3.10/threading.py", line 946, in run
    self._target(*self._args, **self._kwargs)
  File "/home/loupix/Documents/youtubeDownloader/env/lib/python3.10/site-packages/django/utils/autoreload.py", line 64, in wrapper
    fn(*args, **kwargs)
  File "/home/loupix/Documents/youtubeDownloader/env/lib/python3.10/site-packages/channels/management/commands/runserver.py", line 75, in inner_run
    self.check(display_num_errors=True)
  File "/home/loupix/Documents/youtubeDownloader/env/lib/python3.10/site-packages/django/core/management/base.py", line 475, in check
    all_issues = checks.run_checks(
  File "/home/loupix/Documents/youtubeDownloader/env/lib/python3.10/site-packages/django/core/checks/registry.py", line 88, in run_checks
    new_errors = check(app_configs=app_configs, databases=databases)
  File "/home/loupix/Documents/youtubeDownloader/env/lib/python3.10/site-packages/django/core/checks/urls.py", line 14, in check_url_config
    return check_resolver(resolver)
  File "/home/loupix/Documents/youtubeDownloader/env/lib/python3.10/site-packages/django/core/checks/urls.py", line 24, in check_resolver
    return check_method()
  File "/home/loupix/Documents/youtubeDownloader/env/lib/python3.10/site-packages/django/urls/resolvers.py", line 476, in check
    for pattern in self.url_patterns:
  File "/home/loupix/Documents/youtubeDownloader/env/lib/python3.10/site-packages/django/utils/functional.py", line 57, in __get__
    res = instance.__dict__[self.name] = self.func(instance)
  File "/home/loupix/Documents/youtubeDownloader/env/lib/python3.10/site-packages/django/urls/resolvers.py", line 690, in url_patterns
    patterns = getattr(self.urlconf_module, "urlpatterns", self.urlconf_module)
  File "/home/loupix/Documents/youtubeDownloader/env/lib/python3.10/site-packages/django/utils/functional.py", line 57, in __get__
    res = instance.__dict__[self.name] = self.func(instance)
  File "/home/loupix/Documents/youtubeDownloader/env/lib/python3.10/site-packages/django/urls/resolvers.py", line 683, in urlconf_module
    return import_module(self.urlconf_name)
  File "/usr/lib/python3.10/importlib/__init__.py", line 126, in import_module
    return _bootstrap._gcd_import(name[level:], package, level)
  File "<frozen importlib._bootstrap>", line 1050, in _gcd_import
  File "<frozen importlib._bootstrap>", line 1027, in _find_and_load
  File "<frozen importlib._bootstrap>", line 1006, in _find_and_load_unlocked
  File "<frozen importlib._bootstrap>", line 688, in _load_unlocked
  File "<frozen importlib._bootstrap_external>", line 883, in exec_module
  File "<frozen importlib._bootstrap>", line 241, in _call_with_frames_removed
  File "/home/loupix/Documents/youtubeDownloader/youtubeDownload/urls.py", line 24, in <module>
    path('', include('app.urls')),
  File "/home/loupix/Documents/youtubeDownloader/env/lib/python3.10/site-packages/django/urls/conf.py", line 38, in include
    urlconf_module = import_module(urlconf_module)
  File "/usr/lib/python3.10/importlib/__init__.py", line 126, in import_module
    return _bootstrap._gcd_import(name[level:], package, level)
  File "<frozen importlib._bootstrap>", line 1050, in _gcd_import
  File "<frozen importlib._bootstrap>", line 1027, in _find_and_load
  File "<frozen importlib._bootstrap>", line 1006, in _find_and_load_unlocked
  File "<frozen importlib._bootstrap>", line 688, in _load_unlocked
  File "<frozen importlib._bootstrap_external>", line 883, in exec_module
  File "<frozen importlib._bootstrap>", line 241, in _call_with_frames_removed
  File "/home/loupix/Documents/youtubeDownloader/app/urls.py", line 4, in <module>
    from .channels import AppChannels
  File "/home/loupix/Documents/youtubeDownloader/app/channels.py", line 8
    class AppChannels(AsyncJsonWebsocketConsumer):
    ^
IndentationError: expected an indented block after class definition on line 5
/home/loupix/Documents/youtubeDownloader/app/channels.py changed, reloading.
Watching for file changes with StatReloader
Exception in thread django-main-thread:
Traceback (most recent call last):
  File "/usr/lib/python3.10/threading.py", line 1009, in _bootstrap_inner
    self.run()
  File "/usr/lib/python3.10/threading.py", line 946, in run
    self._target(*self._args, **self._kwargs)
  File "/home/loupix/Documents/youtubeDownloader/env/lib/python3.10/site-packages/django/utils/autoreload.py", line 64, in wrapper
    fn(*args, **kwargs)
  File "/home/loupix/Documents/youtubeDownloader/env/lib/python3.10/site-packages/channels/management/commands/runserver.py", line 75, in inner_run
    self.check(display_num_errors=True)
  File "/home/loupix/Documents/youtubeDownloader/env/lib/python3.10/site-packages/django/core/management/base.py", line 475, in check
    all_issues = checks.run_checks(
  File "/home/loupix/Documents/youtubeDownloader/env/lib/python3.10/site-packages/django/core/checks/registry.py", line 88, in run_checks
    new_errors = check(app_configs=app_configs, databases=databases)
  File "/home/loupix/Documents/youtubeDownloader/env/lib/python3.10/site-packages/django/core/checks/urls.py", line 14, in check_url_config
    return check_resolver(resolver)
  File "/home/loupix/Documents/youtubeDownloader/env/lib/python3.10/site-packages/django/core/checks/urls.py", line 24, in check_resolver
    return check_method()
  File "/home/loupix/Documents/youtubeDownloader/env/lib/python3.10/site-packages/django/urls/resolvers.py", line 476, in check
    for pattern in self.url_patterns:
  File "/home/loupix/Documents/youtubeDownloader/env/lib/python3.10/site-packages/django/utils/functional.py", line 57, in __get__
    res = instance.__dict__[self.name] = self.func(instance)
  File "/home/loupix/Documents/youtubeDownloader/env/lib/python3.10/site-packages/django/urls/resolvers.py", line 690, in url_patterns
    patterns = getattr(self.urlconf_module, "urlpatterns", self.urlconf_module)
  File "/home/loupix/Documents/youtubeDownloader/env/lib/python3.10/site-packages/django/utils/functional.py", line 57, in __get__
    res = instance.__dict__[self.name] = self.func(instance)
  File "/home/loupix/Documents/youtubeDownloader/env/lib/python3.10/site-packages/django/urls/resolvers.py", line 683, in urlconf_module
    return import_module(self.urlconf_name)
  File "/usr/lib/python3.10/importlib/__init__.py", line 126, in import_module
    return _bootstrap._gcd_import(name[level:], package, level)
  File "<frozen importlib._bootstrap>", line 1050, in _gcd_import
  File "<frozen importlib._bootstrap>", line 1027, in _find_and_load
  File "<frozen importlib._bootstrap>", line 1006, in _find_and_load_unlocked
  File "<frozen importlib._bootstrap>", line 688, in _load_unlocked
  File "<frozen importlib._bootstrap_external>", line 883, in exec_module
  File "<frozen importlib._bootstrap>", line 241, in _call_with_frames_removed
  File "/home/loupix/Documents/youtubeDownloader/youtubeDownload/urls.py", line 24, in <module>
    path('', include('app.urls')),
  File "/home/loupix/Documents/youtubeDownloader/env/lib/python3.10/site-packages/django/urls/conf.py", line 38, in include
    urlconf_module = import_module(urlconf_module)
  File "/usr/lib/python3.10/importlib/__init__.py", line 126, in import_module
    return _bootstrap._gcd_import(name[level:], package, level)
  File "<frozen importlib._bootstrap>", line 1050, in _gcd_import
  File "<frozen importlib._bootstrap>", line 1027, in _find_and_load
  File "<frozen importlib._bootstrap>", line 1006, in _find_and_load_unlocked
  File "<frozen importlib._bootstrap>", line 688, in _load_unlocked
  File "<frozen importlib._bootstrap_external>", line 883, in exec_module
  File "<frozen importlib._bootstrap>", line 241, in _call_with_frames_removed
  File "/home/loupix/Documents/youtubeDownloader/app/urls.py", line 14, in <module>
    path(r'^ws/test/$', TestChannels.as_asgi()),
NameError: name 'TestChannels' is not defined. Did you mean: 'AppChannels'?
/home/loupix/Documents/youtubeDownloader/app/urls.py changed, reloading.
Watching for file changes with StatReloader
HTTP GET /test/ 200 [0.19, 192.168.1.189:49684]
HTTP GET /favicon.ico 404 [0.23, 192.168.1.189:47034]
HTTP GET /static/build/app.js 200 [0.70, 192.168.1.189:56942]
HTTP GET /test/ 200 [0.02, 192.168.1.189:56816]
HTTP GET /static/build/app.js 304 [0.00, 192.168.1.189:56830]
HTTP GET /test/ 500 [0.63, 192.168.1.189:40420]
HTTP GET /test/ 500 [0.27, 192.168.1.189:57180]
HTTP GET /test/ 500 [0.52, 192.168.1.189:44872]
HTTP GET /test/ 500 [0.35, 192.168.1.189:44874]
HTTP GET /test/ 500 [0.18, 192.168.1.189:58870]
HTTP GET /test/ 500 [0.22, 192.168.1.189:58878]
HTTP GET /test/ 500 [0.22, 192.168.1.189:38326]
